<?xml version="1.0"?>
<robot name="simple_example">
  <material name="Black">
    <color rgba="0.0 0.0 0.0 1.0"/>
  </material>
  <material name="Blue">
    <color rgba="0.0 0.0 0.8 1.0"/>
  </material>
  <material name="Green">
    <color rgba="0.0 0.8 0.0 1.0"/>
  </material>
  <material name="Grey">
    <color rgba="0.4 0.4 0.4 1.0"/>
  </material>
  <material name="Orange">
    <color rgba="1.0 0.423529411765 0.0392156862745 1.0"/>
  </material>
  <material name="Brown">
    <color rgba="0.870588235294 0.811764705882 0.764705882353 1.0"/>
  </material>
  <material name="Red">
    <color rgba="0.8 0.0 0.0 1.0"/>
  </material>
  <material name="White">
    <color rgba="1.0 1.0 1.0 1.0"/>
  </material>

  <link name="base_link">
    
    <inertial>
        <mass value="10" />
        <inertia ixx=" 0.06458333333333335" ixy="0.0" ixz="0.0" iyy=" 0.06458333333333335" iyz="0.0" izz=" 0.06458333333333335"/>
    </inertial>

    <collision>
      <geometry>
        <cylinder radius="0.15" length="0.1" />
      </geometry>
    </collision>
    
    <visual>
      <origin xyz="0.0 0 0.05" rpy="0 0 0" />
      <geometry>
        <cylinder radius="0.15" length="0.1" />
      </geometry>
    <material name="Blue"/>    
    </visual>

  </link>

  <joint name="q1" type="revolute">
    <axis xyz="0 0 1"/>
    <limit effort="100" lower="-3.14" upper="3.14" velocity="1.0"/>
    <parent link="base_link"/>
    <child link="second_link"/>
    <origin  xyz="0.0 0 0.1" rpy="0.0 0.0 1.57"/> 
  </joint>

  <link name="second_link">  
    <inertial>
        <mass value="2.0" />
        <inertia ixx="0.0116666" ixy="0.0" ixz="0.0" iyy="0.0116666" iyz="0.0" izz="0.00105" />
    </inertial>
    <collision>
      <geometry>
        <cylinder radius="0.10" length="0.2" />
      </geometry>
    </collision>
    <visual>
    <origin rpy="0.0 0.0 0.0" xyz="0.0 0.0 0.10" />
      <geometry>
        <cylinder radius="0.10" length="0.2" />
      </geometry>
    <material name="Grey"/>
    </visual>
  </link>

  <joint name="q2" type="revolute">
    <axis xyz="1 0 0"/>
    <limit effort="100" lower="-1.57" upper="1.57" velocity="1.0"/>
    <parent link="second_link"/>
    <child link="third_link"/>
    <origin  xyz="0.0 0 0.2" rpy="0.0 0.0 1.57"/> 
  </joint>


  <link name="third_link">

    <inertial>
        <mass value="2.0" />
        <inertia ixx="0.0116666" ixy="0.0" ixz="0.0" iyy="0.0116666" iyz="0.0" izz="0.00105" />
    </inertial>

    <collision>
      <geometry>
        <cylinder radius="0.08" length="0.15" />
      </geometry>
    </collision>

    <visual>
    <origin rpy="0.0 0 0.0" xyz="0.0 0.0 0.075" />
      <geometry>
        <cylinder radius="0.08" length="0.15"/>
      </geometry>
    <material name="Green"/>
    </visual>
  </link>


  <joint name="q3" type="revolute">
    <axis xyz="1 0 0"/>
    <limit effort="10" lower="-1.57" upper="1.57" velocity="1.0"/>
    <parent link="third_link"/>
    <child link="fourth_link"/>
    <origin  xyz="0.0 0 0.15" rpy="0.0 0.0 1.57"/> 
  </joint>

  <link name="fourth_link"> 
    <inertial>
        <mass value="0.18" />
        <inertia ixx="0.00105" ixy="0.0" ixz="0.0" iyy="0.00105" iyz="0.0" izz="0.00105" />
    </inertial>

    <collision>
      <geometry>
        <cylinder radius="0.08" length="0.3" />
      </geometry>
    </collision>

    <visual>
    <origin rpy="0.0 0 0.0" xyz="0.0 0.0 0.15" />
      <geometry>
        <cylinder radius="0.06" length="0.3" />
      </geometry>
    <material name="Grey"/>
    </visual>
  </link>

  <joint name="q4" type="revolute">
    <axis xyz="0 1 0"/>
    <limit effort="50" lower="-1.57" upper="1.57" velocity="1.0"/>
    <parent link="fourth_link"/>
    <child link="fifth_link"/>
    <origin  xyz="0.0 0 0.3" rpy="0.0 0.0 1.57"/> 
  </joint>

  <link name="fifth_link"> 
    <inertial>
        <mass value="0.18" />
        <inertia ixx="0.00105" ixy="0.0" ixz="0.0" iyy="0.00105" iyz="0.0" izz="0.00105" />
    </inertial>

    <collision>
      <geometry>
        <cylinder radius="0.06" length="0.15" />
      </geometry>
    </collision>

    <visual>
    <origin rpy="0.0 0 0.0" xyz="0.0 0.0 0.075" />
      <geometry>
        <cylinder radius="0.06" length="0.15" />
      </geometry>
    <material name="Green"/>    
    </visual>
  </link>

  <joint name="q5" type="revolute">
    <axis xyz="1 0 0"/>
    <limit effort="50" lower="-1.57" upper="1.57" velocity="1.0"/>
    <parent link="fifth_link"/>
    <child link="sixth_link"/>
    <origin  xyz="0.0 0 0.15" rpy="0.0 0.0 1.57"/> 
  </joint>


  <link name="sixth_link"> 
    <inertial>
        <mass value="0.1" />
        <inertia ixx="0.00105" ixy="0.0" ixz="0.0" iyy="0.00105" iyz="0.0" izz="0.00105" />
    </inertial>

    <collision>
      <geometry>
        <cylinder radius="0.06" length="0.10" />
      </geometry>
    </collision>

    <visual>
    <origin rpy="0.0 0 0.0" xyz="0.0 0.0 0.05" />
      <geometry>
        <cylinder radius="0.06" length="0.1" />
      </geometry>
    <material name="Grey"/>
    </visual>
  </link>

  <joint name="q6" type="revolute">
    <axis xyz="0 0 1"/>
    <limit effort="50" lower="-3.14" upper="3.14" velocity="1.0"/>
    <parent link="sixth_link"/>
    <child link="seventh_link"/>
    <origin  xyz="0.0 0 0.10" rpy="0.0 0.0 1.57"/> 
  </joint>


  <link name="seventh_link"> 
    <inertial>
        <mass value="0.1" />
        <inertia ixx="0.00105" ixy="0.0" ixz="0.0" iyy="0.00105" iyz="0.0" izz="0.00105" />
    </inertial>

    <collision>
      <geometry>
        <cylinder radius="0.06" length="0.10" />
      </geometry>
    </collision>

    <visual>
    <origin rpy="0.0 0 0.0" xyz="0.0 0.0 0.05" />
      <geometry>
        <cylinder radius="0.06" length="0.1" />
      </geometry>
    <material name="Blue"/>    
    </visual>
  </link>



<gazebo>
  <plugin name="gazebo_ros_control" filename="libgazebo_ros_control.so">
    <robotNamespace>/manipulator</robotNamespace>
    <robotSimType>gazebo_ros_control/DefaultRobotHWSim</robotSimType>
  </plugin>
</gazebo>


  <transmission name="tran1">
    <type>transmission_interface/SimpleTransmission</type>
    <joint name="q1">
      <hardwareInterface>hardware_interface/EffortJointInterface</hardwareInterface>
    </joint>
    <actuator name="motor1">
      <hardwareInterface>hardware_interface/EffortJointInterface</hardwareInterface>
      <mechanicalReduction>1</mechanicalReduction>
    </actuator>
  </transmission>

   <transmission name="tran2">
    <type>transmission_interface/SimpleTransmission</type>
    <joint name="q2">
      <hardwareInterface>hardware_interface/EffortJointInterface</hardwareInterface>
    </joint>
    <actuator name="motor2">
      <hardwareInterface>hardware_interface/EffortJointInterface</hardwareInterface>
      <mechanicalReduction>1</mechanicalReduction>
    </actuator>
  </transmission> 

  <transmission name="tran3">
    <type>transmission_interface/SimpleTransmission</type>
    <joint name="q3">
      <hardwareInterface>hardware_interface/EffortJointInterface</hardwareInterface>
    </joint>
    <actuator name="motor3">
      <hardwareInterface>hardware_interface/EffortJointInterface</hardwareInterface>
      <mechanicalReduction>1</mechanicalReduction>
    </actuator>
  </transmission>

   <transmission name="tran4">
    <type>transmission_interface/SimpleTransmission</type>
    <joint name="q4">
      <hardwareInterface>hardware_interface/EffortJointInterface</hardwareInterface>
    </joint>
    <actuator name="motor4">
      <hardwareInterface>hardware_interface/EffortJointInterface</hardwareInterface>
      <mechanicalReduction>1</mechanicalReduction>
    </actuator>
  </transmission> 

  <transmission name="tran5">
    <type>transmission_interface/SimpleTransmission</type>
    <joint name="q5">
      <hardwareInterface>hardware_interface/EffortJointInterface</hardwareInterface>
    </joint>
    <actuator name="motor5">
      <hardwareInterface>hardware_interface/EffortJointInterface</hardwareInterface>
      <mechanicalReduction>1</mechanicalReduction>
    </actuator>
  </transmission>

   <transmission name="tran6">
    <type>transmission_interface/SimpleTransmission</type>
    <joint name="q6">
      <hardwareInterface>hardware_interface/EffortJointInterface</hardwareInterface>
    </joint>
    <actuator name="motor6">
      <hardwareInterface>hardware_interface/EffortJointInterface</hardwareInterface>
      <mechanicalReduction>1</mechanicalReduction>
    </actuator>
  </transmission> 

</robot>